Workbook
Name Awareness: References!$M$3:$M$7
Name EaseofExploit: References!$K$3:$K$7
Name EasyofDiscovery: References!$I$3:$I$7
Name FinancialDamage: References!$I$12:$I$16
Name IntrusionDetection: References!$O$3:$O$7
Name LossofAccountability: References!$G$12:$G$15
Name LossofAvailability: References!$E$12:$E$16
Name LossofConfidentiality: References!$A$12:$A$16
Name LossofIntegrity: References!$C$12:$C$17
Name Motive: References!$C$3:$C$6
Name NonCompliance: References!$M$12:$M$15
Name Opportunity: References!$E$3:$E$6
Name PolicyViolation: References!$O$12:$O$16
Name PopulationSize: References!$G$3:$G$8
Name ReputationDamage: References!$K$12:$K$16
Name result: #REF!
Name SkillRequired: References!$A$3:$A$8

Sheet Testing Checklist
B1: OWASP: Testing Guide Checklist
B5: Information Gathering | C5: Test Name | D5: Objectives | E5: Status | F5: Notes
B6: WSTG-INFO-01 | C6: =HYPERLINK("https://owasp.org/www-project-web-security-testing-guide/latest/4-Web_Application_Security_Testing/01-Information_Gathering/01-Conduct_Search_Engine_Reconnaissance_for_Information_Leakage", "Realizar reconocimiento de motores de búsqueda para detectar filtraciones de información") | D6: N/A | E6: Not Started
B7: WSTG-INFO-02 | C7: =HYPERLINK("https://owasp.org/www-project-web-security-testing-guide/latest/4-Web_Application_Security_Testing/01-Information_Gathering/02-Fingerprint_Web_Server", "Identificación del servidor web") | D7: N/A | E7: Not Started
B8: WSTG-INFO-03 | C8: =HYPERLINK("https://owasp.org/www-project-web-security-testing-guide/latest/4-Web_Application_Security_Testing/01-Information_Gathering/03-Review_Webserver_Metafiles_for_Information_Leakage", "Revisar los archivos de metadatos del servidor web para detectar fugas de información") | D8: N/A | E8: Not Started
B9: WSTG-INFO-04 | C9: =HYPERLINK("https://owasp.org/www-project-web-security-testing-guide/latest/4-Web_Application_Security_Testing/01-Information_Gathering/04-Attack_Surface_Identification", "Identificación de la superficie de ataque") | D9: N/A | E9: Not Started
B10: WSTG-INFO-05 | C10: =HYPERLINK("https://owasp.org/www-project-web-security-testing-guide/latest/4-Web_Application_Security_Testing/01-Information_Gathering/05-Review_Web_Page_Content_for_Information_Leakage", "Revisar el contenido de las páginas web para detectar fugas de información") | D10: N/A | E10: Not Started
B11: WSTG-INFO-06 | C11: =HYPERLINK("https://owasp.org/www-project-web-security-testing-guide/latest/4-Web_Application_Security_Testing/01-Information_Gathering/06-Identify_Application_Entry_Points", "Identificar los puntos de entrada de la aplicación") | D11: N/A | E11: Not Started
B12: WSTG-INFO-07 | C12: =HYPERLINK("https://owasp.org/www-project-web-security-testing-guide/latest/4-Web_Application_Security_Testing/01-Information_Gathering/07-Map_Execution_Paths_Through_Application", "Mapear las rutas de ejecución de la aplicación") | D12: N/A | E12: Not Started
B13: WSTG-INFO-08 | C13: =HYPERLINK("https://owasp.org/www-project-web-security-testing-guide/latest/4-Web_Application_Security_Testing/01-Information_Gathering/08-Fingerprint_Web_Application_Framework", "Identificar la huella digital del framework de una aplicación web") | D13: N/A | E13: Not Started
B14: WSTG-INFO-09 | C14: =HYPERLINK("https://owasp.org/www-project-web-security-testing-guide/latest/4-Web_Application_Security_Testing/01-Information_Gathering/09-Fingerprint_Web_Application", "Huella digital de la aplicación web") | D14: N/A | E14: Not Started
B15: WSTG-INFO-10 | C15: =HYPERLINK("https://owasp.org/www-project-web-security-testing-guide/latest/4-Web_Application_Security_Testing/01-Information_Gathering/10-Map_Application_Architecture", "Mapear la arquitectura de la aplicación") | D15: N/A | E15: Not Started
B17: Configuration and Deployment Management | C17: Test Name | D17: Objectives | E17: Status | F17: Notes
B18: WSTG-CONF-01 | C18: =HYPERLINK("https://owasp.org/www-project-web-security-testing-guide/latest/4-Web_Application_Security_Testing/02-Configuration_and_Deployment_Management/01-Network_Infrastructure_Configuration", "Configuración de la infraestructura de red") | D18: N/A | E18: Not Started
B19: WSTG-CONF-02 | C19: =HYPERLINK("https://owasp.org/www-project-web-security-testing-guide/latest/4-Web_Application_Security_Testing/02-Configuration_and_Deployment_Management/02-Application_Platform_Configuration", "Configuración de la plataforma de aplicación") | D19: N/A | E19: Not Started
B20: WSTG-CONF-03 | C20: =HYPERLINK("https://owasp.org/www-project-web-security-testing-guide/latest/4-Web_Application_Security_Testing/02-Configuration_and_Deployment_Management/03-File_Extensions_Handling_for_Sensitive_Information", "Manejo de extensiones de archivo para información sensible") | D20: N/A | E20: Not Started
B21: WSTG-CONF-04 | C21: =HYPERLINK("https://owasp.org/www-project-web-security-testing-guide/latest/4-Web_Application_Security_Testing/02-Configuration_and_Deployment_Management/04-Review_Old_Backup_and_Unreferenced_Files_for_Sensitive_Information", "Revisar archivos antiguos de respaldo y no referenciados en busca de información sensible") | D21: N/A | E21: Not Started
B22: WSTG-CONF-05 | C22: =HYPERLINK("https://owasp.org/www-project-web-security-testing-guide/latest/4-Web_Application_Security_Testing/02-Configuration_and_Deployment_Management/05-Enumerate_Infrastructure_and_Application_Admin_Interfaces", "Enumerar interfaces de administración de infraestructura y aplicaciones") | D22: N/A | E22: Not Started
B23: WSTG-CONF-06 | C23: =HYPERLINK("https://owasp.org/www-project-web-security-testing-guide/latest/4-Web_Application_Security_Testing/02-Configuration_and_Deployment_Management/06-HTTP_Methods", "Métodos HTTP") | D23: N/A | E23: Not Started
B24: WSTG-CONF-07 | C24: =HYPERLINK("https://owasp.org/www-project-web-security-testing-guide/latest/4-Web_Application_Security_Testing/02-Configuration_and_Deployment_Management/07-HTTP_Strict_Transport_Security", "HTTP Strict Transport Security") | D24: N/A | E24: Not Started
B25: WSTG-CONF-08 | C25: =HYPERLINK("https://owasp.org/www-project-web-security-testing-guide/latest/4-Web_Application_Security_Testing/02-Configuration_and_Deployment_Management/08-RIA_Cross_Domain_Policy", "Política de dominio cruzado de RIA") | D25: N/A | E25: Not Started
B26: WSTG-CONF-09 | C26: =HYPERLINK("https://owasp.org/www-project-web-security-testing-guide/latest/4-Web_Application_Security_Testing/02-Configuration_and_Deployment_Management/09-File_Permissions", "Permisos de archivos") | D26: N/A | E26: Not Started
B27: WSTG-CONF-10 | C27: =HYPERLINK("https://owasp.org/www-project-web-security-testing-guide/latest/4-Web_Application_Security_Testing/02-Configuration_and_Deployment_Management/10-Subdomain_Takeover", "Secuestro de subdominios") | D27: N/A | E27: Not Started
B28: WSTG-CONF-11 | C28: =HYPERLINK("https://owasp.org/www-project-web-security-testing-guide/latest/4-Web_Application_Security_Testing/02-Configuration_and_Deployment_Management/11-Cloud_Storage", "Almacenamiento en la nube") | D28: N/A | E28: Not Started
B29: WSTG-CONF-12 | C29: =HYPERLINK("https://owasp.org/www-project-web-security-testing-guide/latest/4-Web_Application_Security_Testing/02-Configuration_and_Deployment_Management/12-Content_Security_Policy", "Política de seguridad de contenido") | D29: N/A | E29: Not Started
B30: WSTG-CONF-13 | C30: =HYPERLINK("https://owasp.org/www-project-web-security-testing-guide/latest/4-Web_Application_Security_Testing/02-Configuration_and_Deployment_Management/13-Path_Confusion", "Confusión de rutas") | D30: N/A | E30: Not Started
B31: WSTG-CONF-14 | C31: =HYPERLINK("https://owasp.org/www-project-web-security-testing-guide/latest/4-Web_Application_Security_Testing/02-Configuration_and_Deployment_Management/14-Other_HTTP_Security_Header_Misconfigurations", "Otras configuraciones incorrectas de encabezados de seguridad HTTP") | D31: N/A | E31: Not Started
B32: WSTG-CONF-15 | C32: =HYPERLINK("https://owasp.org/www-project-web-security-testing-guide/latest/4-Web_Application_Security_Testing/02-Configuration_and_Deployment_Management/15-Feature_Flag_Security_Bypass", "Evasión de seguridad mediante indicadores de funcionalidad") | D32: N/A | E32: Not Started
B34: Identity Management | C34: Test Name | D34: Objectives | E34: Status | F34: Notes
B35: WSTG-IDNT-01 | C35: =HYPERLINK("https://owasp.org/www-project-web-security-testing-guide/latest/4-Web_Application_Security_Testing/03-Identity_Management/01-Role_Definitions", "Definiciones de roles") | D35: N/A | E35: Not Started
B36: WSTG-IDNT-02 | C36: =HYPERLINK("https://owasp.org/www-project-web-security-testing-guide/latest/4-Web_Application_Security_Testing/03-Identity_Management/02-User_Registration_Process", "Proceso de registro de usuarios") | D36: N/A | E36: Not Started
B37: WSTG-IDNT-03 | C37: =HYPERLINK("https://owasp.org/www-project-web-security-testing-guide/latest/4-Web_Application_Security_Testing/03-Identity_Management/03-Account_Provisioning_Process", "Proceso de aprovisionamiento de cuentas") | D37: N/A | E37: Not Started
B38: WSTG-IDNT-04 | C38: =HYPERLINK("https://owasp.org/www-project-web-security-testing-guide/latest/4-Web_Application_Security_Testing/03-Identity_Management/04-Account_Enumeration_and_Guessable_User_Account", "Enumeración de cuentas y cuentas de usuario adivinables") | D38: N/A | E38: Not Started
B39: WSTG-IDNT-05 | C39: =HYPERLINK("https://owasp.org/www-project-web-security-testing-guide/latest/4-Web_Application_Security_Testing/03-Identity_Management/05-Weak_or_Unenforced_Username_Policy", "Política de nombres de usuario débil o no aplicada") | D39: N/A | E39: Not Started
B41: Authentication | C41: Test Name | D41: Objectives | E41: Status | F41: Notes
B42: WSTG-ATHN-01 | C42: =HYPERLINK("https://owasp.org/www-project-web-security-testing-guide/latest/4-Web_Application_Security_Testing/04-Authentication/01-Credentials_Transported_over_an_Encrypted_Channel", "Prueba de credenciales transportadas a través de un canal cifrado") | D42: N/A | E42: Not Started
B43: WSTG-ATHN-02 | C43: =HYPERLINK("https://owasp.org/www-project-web-security-testing-guide/latest/4-Web_Application_Security_Testing/04-Authentication/02-Default_Credentials", "Credenciales predeterminadas") | D43: N/A | E43: Not Started
B44: WSTG-ATHN-03 | C44: =HYPERLINK("https://owasp.org/www-project-web-security-testing-guide/latest/4-Web_Application_Security_Testing/04-Authentication/03-Weak_Lock_Out_Mechanism", "Mecanismo de bloqueo débil") | D44: N/A | E44: Not Started
B45: WSTG-ATHN-04 | C45: =HYPERLINK("https://owasp.org/www-project-web-security-testing-guide/latest/4-Web_Application_Security_Testing/04-Authentication/04-Bypassing_Authentication_Schema", "Omisión del esquema de autenticación") | D45: N/A | E45: Not Started
B46: WSTG-ATHN-05 | C46: =HYPERLINK("https://owasp.org/www-project-web-security-testing-guide/latest/4-Web_Application_Security_Testing/04-Authentication/05-Vulnerable_Remember_Password", "Contraseña recordada vulnerable") | D46: N/A | E46: Not Started
...

Sheet Summary Findings
B1: OWASP: Summary Findings
B3: Nº | C3: OTG | D3: Vulnerability Name | E3: Affected Host/Path | F3: Impact | G3: Likelihood | H3: Risk | I3: Observation/Implication | J3: Recommendation | K3: Test Evidence
B4: 1 | C4: WSTG-INFO-02 | D4: {=INDEX('Testing Checklist'!C:C,MATCH(C4,'Testing Checklist'!B:B,0))} | E4: www.example.com/news.php (id,page) | F4: High | G4: Moderate | H4: High | K4: xxx-1
B5: 2 | C5: WSTG-INFO-02 | D5: Conduct Search Engine Discovery Reconnaissance for Information Leakage | E5: www.example.com/news.php (id,page) | F5: High | G5: Moderate | H5: High
B6: 3 | C6: WSTG-INFO-02 | D6: Conduct Search Engine Discovery Reconnaissance for Information Leakage | E6: www.example.com/news.php (id,page) | F6: High | G6: Moderate | H6: High

Sheet Risk Assessment Calculator
B1: OWASP: Risk Assessment Calculator
B3: Likelihood factors | G3: Impact factors
B4: Threat Agent Factors | G4: Technical Impact Factors
B5: Skills required | C5: Some technical skills [3] | F5: =VLOOKUP(C5,References!A2:B8,2,0) | G5: Loss of confidentiality | H5: Minimal non-sensitive data disclosed [2] | I5: =VLOOKUP(H5,References!A$11:B$16,2,0)
B6: Motive | C6: Possible reward [4] | F6: =VLOOKUP(C6,References!C2:D6,2,0) | G6: Loss of Integrity | H6: All data totally corrupt [9] | I6: =VLOOKUP(H6,References!C$11:D$17,2,0)
B7: Opportunity | C7: Full access or expensive resources required [0] | F7: =VLOOKUP(C7,References!E2:F6,2,0) | G7: Loss of Availability | H7: Minimal secondary services interrupted [1] | I7: =VLOOKUP(H7,References!E$11:F$16,2,0)
B8: Population Size | C8: System Administrators [2] | F8: =VLOOKUP(C8,References!G3:H8,2,0) | G8: Loss of Accountability | H8: Not Applicable [0] | I8: =VLOOKUP(H8,References!G$11:H$16,2,0)
B10: Vulnerability Factors | G10: Business Impact Factors
B11: Easy of Discovery | C11: Practically impossible [1] | F11: =VLOOKUP(C11,References!I2:J7,2,0) | G11: Financial damage | H11: Minor effect on annual profit [3] | I11: =VLOOKUP(H11,References!I$11:J$16,2,0)
B12: Ease of Exploit | C12: Easy [5] | F12: =VLOOKUP(C12,References!K$2:L$7,2,0) | G12: Reputation damage | H12: Loss of major accounts [4] | I12: =VLOOKUP(H12,References!K$11:L$16,2,0)
B13: Awareness | C13: Hidden [4] | F13: =VLOOKUP(C13,References!M$2:N$7,2,0) | G13: Non-Compliance | H13: Clear violation [5] | I13: =VLOOKUP(H13,References!M$11:O$16,2,0)
B14: Intrusion Detection | C14: Logged and reviewed [3] | F14: =VLOOKUP(C14,References!O$2:P$7,2,0) | G14: Privacy violation | H14: One individual [3] | I14: =VLOOKUP(H14,References!O$11:P$16,2,0)
B16: Likelihood score: | C16: =IFERROR(AVERAGE(F5:F8,F11:F14),"All factors require a selection.") | G16: Impact score: | H16: =IFERROR(AVERAGE(I5:I8,I11:I14),"All factors require a selection.")
B20: Overall Risk Severity : | E20: =IFERROR(IF(AND($C$16<3,$H$16<3),"Note",IF(OR(AND($C$16<3,$H$16>=3,$H$16<6),AND($C$16>=3,$C$16<6,$H$16<3)),"Low",IF(OR(AND($C16<3,$H16>=6),AND($C16>=3,$C16<6,$H16>=3,$H16<6),AND($C16>=6,$H16<3)),"MODERATE",IF(OR(AND($C16>=6,$C16>=3,$H16<6),AND($C16>=3,$C16<6,$H16>6)),"High","Critical")))),"Note")
C22: Impact
B23: Likelihood | C23: =IF($H16<3,"->Low<-","Low") | D23: =IF(AND($H16>=3,$H16<6),"->Moderate<-","Moderate") | E23: =IF($H16>=6,"->High<-","High")
B24: =IF($C16<3,"->Low<-","Low") | C24: =IF(AND($C$16<3,$H$16<3),"->Note<-","Note") | D24: =IF(AND($C$16<3,$H$16>=3,$H$16<6),"->Low<-","Low") | E24: =IF(AND($C16<3,$H16>=6),"->Moderate<-","Moderate")
B25: =IF(AND($C16>=3,$C16<6),"->Moderate<-","Moderate") | C25: =IF(AND($C$16>=3,$C$16<6,$H$16<3),"->Low<-","Low") | D25: =IF(AND($C16>=3,$C16<6,$H16>=3,$H16<6),"->Moderate<-","Moderate") | E25: =IF(AND($C16>=3,$C16<6,$H16>6),"->High<-","High")
B26: =IF($C16>=6,"->High<-","High") | C26: =IF(AND($C16>=6,$H16<3),"->Moderate<-","Moderate") | D26: =IF(AND($C16>=6,$C16>=3,$H16<6),"->High<-","High") | E26: =IF(AND($C$16>=6,$H$16>=6),"->Critical<-","Critical")

Sheet References
A1: Skills required | C1: Motive | E1: Opportunity | G1: Population Size | I1: Easy of Discovery | K1: Ease of Exploit | M1: Awareness | O1: Intrusion Detection
A2: Select an option | C2: Select an option | E2: Select an option | G2: Select an option | I2: Select an option | K2: Select an option | M2: Select an option | O2: Select an option
A3: Not Applicable [0] | B3: 0 | C3: Not Applicable [0] | D3: 0 | E3: Full access or expensive resources required [0] | F3: 0 | G3: Not Applicable [0] | H3: 0 | I3: Not Applicable [0] | J3: 0 | K3: Not Applicable [0] | L3: 0 | M3: Not Applicable [0] | N3: 0 | O3: Not Applicable [0] | P3: 0
A4: No technical skills [1] | B4: 1 | C4: Low or no reward [1] | D4: 1 | E4: Special access or resources required [4] | F4: 4 | G4: System Administrators [2] | H4: 2 | I4: Practically impossible [1] | J4: 1 | K4: Theoretical [1] | L4: 1 | M4: Unknown [1] | N4: 1 | O4: Active detection in application [1] | P4: 1
A5: Some technical skills [3] | B5: 3 | C5: Possible reward [4] | D5: 4 | E5: Some access or resources required [7] | F5: 7 | G5: Intranet Users [4] | H5: 4 | I5: Difficult [3] | J5: 3 | K5: Difficult [3] | L5: 3 | M5: Hidden [4] | N5: 4 | O5: Logged and reviewed [3] | P5: 3
A6: Advanced computer user [5] | B6: 5 | C6: High reward [9] | D6: 9 | E6: No access or resources required [9] | F6: 9 | G6: Partners [5] | H6: 5 | I6: Easy [7] | J6: 7 | K6: Easy [5] | L6: 5 | M6: Obvious [6] | N6: 6 | O6: Logged without review [8] | P6: 8
A7: Network and programming skills [6] | B7: 6 | G7: Authenticated users [6] | H7: 6 | I7: Automated tools available [9] | J7: 9 | K7: Automated tools available [9] | L7: 9 | M7: Public knowledge [9] | N7: 9 | O7: Not logged [9] | P7: 9
A8: Security penetration skills [9] | B8: 9 | G8: Anonymous Internet users [9] | H8: 9
A10: Loss of confidentiality | C10: Loss of Integrity | E10: Loss of Availability | G10: Loss of Accountability | I10: Financial damage | K10: Reputation damage | M10: Non-Compliance | O10: Privacy violation
A11: Select an option | C11: Select an option | E11: Select an option | G11: Select an option | I11: Select an option | K11: Select an option | M11: Select an option | O11: Select an option
A12: Not Applicable [0] | B12: 0 | C12: Not Applicable [0] | D12: 0 | E12: Not Applicable [0] | F12: 0 | G12: Not Applicable [0] | H12: 0 | I12: Not Applicable [0] | J12: 0 | K12: Not Applicable [0] | L12: 0 | M12: Not Applicable [0] | N12: 0 | O12: Not Applicable [0] | P12: 0
A13: Minimal non-sensitive data disclosed [2] | B13: 2 | C13: Minimal slightly corrupt data [1] | D13: 1 | E13: Minimal secondary services interrupted [1] | F13: 1 | G13: Attack fully traceable to individual [1] | H13: 1 | I13: Damage costs less than to fix the issue [1] | J13: 1 | K13: Minimal damage [1] | L13: 1 | M13: Minor violation [2] | N13: 2 | O13: One individual [3] | P13: 3
A14: Extensive non-sensitive data disclosed [6] | B14: 6 | C14: Minimal seriously corrupt data [3] | D14: 3 | E14: Minimal primary services interrupted [5] | F14: 5 | G14: Attack possibly traceable to individual [7] | H14: 7 | I14: Minor effect on annual profit [3] | J14: 3 | K14: Loss of major accounts [4] | L14: 4 | M14: Clear violation [5] | N14: 5 | O14: Hundreds of people [5] | P14: 5
A15: Extensive critical data disclosed [7] | B15: 7 | C15: Extensive slightly corrupt data [5] | D15: 5 | E15: Extensive primary services interrupted [7] | F15: 7 | G15: Attack completely anonymous [9] | H15: 9 | I15: Significant effect on annual profit [7] | J15: 7 | K15: Loss of goodwill [5] | L15: 5 | M15: High profile violation [7] | N15: 7 | O15: Thousands of people [7] | P15: 7
A16: All data disclosed [9] | B16: 9 | C16: Extensive seriously corrupt data [7] | D16: 7 | E16: All services completely lost [9] | F16: 9 | I16: Backruptcy [9] | J16: 9 | K16: Brand damage [9] | L16: 9 | O16: Millions of people [9] | P16: 9
C17: All data totally corrupt [9] | D17: 9
